Workbook

Sheet mybt
A1: id | B1: year | C1: company | D1: capital | E1: office | F1: yearg | G1: situated | H1: mine | I1: loc | J1: text | K1: lastname | L1: firstname | M1: middlename | N1: prof | O1: company | P1: capital | Q1: office | R1: yearg | S1: situated | T1: mine | U1: loc | V1: lastname | W1: firstname | X1: middlename | Y1: prof | Z1: cerco | AA1: totco | AB1: extracted/actual | AC1: positive | AD1: negative
A2: myb1734 | B2: 1887 | C2: AUSTRIAN OZOKERIT COMPANY | I2: kensington | J2: C. J. Elers, 6 Kensington Court | Z2: 0 | AA2: =LEN(C2)+LEN(D2)+LEN(E2)+LEN(F2)+LEN(G2)+LEN(H2)+LEN(I2)+LEN(K2)+LEN(L2)+LEN(M2)+LEN(N2) -> 35 | AB2: positive | AC2: t | AD2: f
A3: myb6799 | B3: 1887 | C3: COMPANY LIMITED | I3: mysore | J3: over by the Mysore- Wynaad Consolidated Gold Mining Company, Limited. | O3: b | Z3: 23 | AA3: =LEN(C3)+LEN(D3)+LEN(E3)+LEN(F3)+LEN(G3)+LEN(H3)+LEN(I3)+LEN(K3)+LEN(L3)+LEN(M3)+LEN(N3) -> 21 | AB3: negative | AC3: f | AD3: t
A4: myb13850 | B4: 1887 | C4: MOUNT TAOAHONG EXPLOBATION | I4: london | J4: The dividend for 1685 was 5 per cent., and for 1886, 6 per cent. The | Z4: {=+Z4:AZ4:Z397} -> 0 | AA4: =LEN(C4)+LEN(D4)+LEN(E4)+LEN(F4)+LEN(G4)+LEN(H4)+LEN(I4)+LEN(K4)+LEN(L4)+LEN(M4)+LEN(N4) -> 32
A5: myb14328 | B5: 1887 | C5: MORFA DU MINING COMPANY | I5: london | J5: limited. | AA5: =LEN(C5)+LEN(D5)+LEN(E5)+LEN(F5)+LEN(G5)+LEN(H5)+LEN(I5)+LEN(K5)+LEN(L5)+LEN(M5)+LEN(N5) -> 29 | AB5: code
A6: myb17600 | B6: 1887 | C6: OPAL MINES OF QUEENSLAND LIMITED | I6: queensland | J6: shares, of which 15,000 were taken by the vendor in addition to £27,500 in cash | AA6: =LEN(C6)+LEN(D6)+LEN(E6)+LEN(F6)+LEN(G6)+LEN(H6)+LEN(I6)+LEN(K6)+LEN(L6)+LEN(M6)+LEN(N6) -> 42 | AB6: extracted/actual | AC6: positive | AD6: negative
A7: myb19077 | B7: 1887 | C7: POLYEAR TIN MINING COMPANY LIMITED | D7: 48520.136 | I7: cornwall | J7: The capital is £10,000 in shares of £1 each. | AA7: =LEN(C7)+LEN(D7)+LEN(E7)+LEN(F7)+LEN(G7)+LEN(H7)+LEN(I7)+LEN(K7)+LEN(L7)+LEN(M7)+LEN(N7) -> 53 | AB7: positive | AD7: f
A8: myb19678 | B8: 1887 | C8: RAVENSCLIFF MINING COMPANY LIMITED | I8: new zealand | J8: necessary capital, to comply with the terms of the Act in this respect within a reasonable | AA8: =LEN(C8)+LEN(D8)+LEN(E8)+LEN(F8)+LEN(G8)+LEN(H8)+LEN(I8)+LEN(K8)+LEN(L8)+LEN(M8)+LEN(N8) -> 45 | AB8: negative | AC8: f
A9: myb20945 | B9: 1887 | C9: COMPANY LIMITED | E9: broad street london | I9: winchester | J9: 1, Winchester House, Old Broad Street, E.C. | O9: b | AA9: =LEN(C9)+LEN(D9)+LEN(E9)+LEN(F9)+LEN(G9)+LEN(H9)+LEN(I9)+LEN(K9)+LEN(L9)+LEN(M9)+LEN(N9) -> 44
A10: myb21637 | B10: 1887 | C10: PLUMAS EUREKA MINE | I10: plumas | J10: Seventy-Six Mine, 6,003 tons; Seventy-Six Ravine Mine, 8,160 tons; Elizal eth Mine, 20; | AA10: =LEN(C10)+LEN(D10)+LEN(E10)+LEN(F10)+LEN(G10)+LEN(H10)+LEN(I10)+LEN(K10)+LEN(L10)+LEN(M10)+LEN(N10) -> 24 | AB10: types of mistakes on true positives
A11: myb23491 | B11: 1887 | C11: TINDENE MINING COMPANY LIMITED | I11: aldersgate street merchant | J11: .1. M Call, Whipps Cross, Walthamstow, provision merchant 800 | AA11: =LEN(C11)+LEN(D11)+LEN(E11)+LEN(F11)+LEN(G11)+LEN(H11)+LEN(I11)+LEN(K11)+LEN(L11)+LEN(M11)+LEN(N11) -> 56 | AB11: no mistake
A12: myb27537 | B12: 1888 | C12: BELL STONE SLATE QUARRIES COMPANY | I12: broadway | J12: 1886 £4,329. | AA12: =LEN(C12)+LEN(D12)+LEN(E12)+LEN(F12)+LEN(G12)+LEN(H12)+LEN(I12)+LEN(K12)+LEN(L12)+LEN(M12)+LEN(N12) -> 41 | AB12: source to text (OCR misreads the text, extra spaces, wrong characters, etc.) | AC12: a
A13: myb31676 | B13: 1888 | C13: DAN O CONNELL GOLD MINING COMPANY | I13: london | J13: comprising togother an area of about 50 acres, both held under the usual | AA13: =LEN(C13)+LEN(D13)+LEN(E13)+LEN(F13)+LEN(G13)+LEN(H13)+LEN(I13)+LEN(K13)+LEN(L13)+LEN(M13)+LEN(N13) -> 39 | AB13: text to classification | AC13: b
A14: myb32402 | B14: 1888 | C14: DISRAELI MINE SYNDICATE COMPANY LIMITED | F14: 1885 | I14: broad street b | J14: This company was registered on the 10th February, 1885, to acquire and work a | AA14: =LEN(C14)+LEN(D14)+LEN(E14)+LEN(F14)+LEN(G14)+LEN(H14)+LEN(I14)+LEN(K14)+LEN(L14)+LEN(M14)+LEN(N14) -> 57
A15: myb37847 | B15: 1888 | C15: LINARES LEAD MINING COMPANY LIMITED | I15: linares | J15: 1875 . 15s. Od. | AA15: =LEN(C15)+LEN(D15)+LEN(E15)+LEN(F15)+LEN(G15)+LEN(H15)+LEN(I15)+LEN(K15)+LEN(L15)+LEN(M15)+LEN(N15) -> 42 | AB15: Progress indicator
A16: myb42349 | B16: 1888 | C16: DIRECTORS | I16: new zealand | J16: experienced, which have much delayed progress, but your directors are pleased to report that | O16: b | AA16: =LEN(C16)+LEN(D16)+LEN(E16)+LEN(F16)+LEN(G16)+LEN(H16)+LEN(I16)+LEN(K16)+LEN(L16)+LEN(M16)+LEN(N16) -> 20
A17: myb43124 | B17: 1888 | C17: NORTH KENNEDY COMPANY LIMITED | I17: wales | J17: extraction. The directors hero particularly refer to the discovery made iu the Fort una level ; which, according to the last advices received, is already sending to the crusher mineral of the | O17: b | U17: b | AA17: =LEN(C17)+LEN(D17)+LEN(E17)+LEN(F17)+LEN(G17)+LEN(H17)+LEN(I17)+LEN(K17)+LEN(L17)+LEN(M17)+LEN(N17) -> 34
A18: myb45795 | B18: 1888 | C18: REMEDIOS COLOMBIA UNITED GOLD MINES | I18: bolivia | J18: amount of £4,400 were also issued in exchange for the debentures of the old | AA18: =LEN(C18)+LEN(D18)+LEN(E18)+LEN(F18)+LEN(G18)+LEN(H18)+LEN(I18)+LEN(K18)+LEN(L18)+LEN(M18)+LEN(N18) -> 42
A19: myb47091 | B19: 1888 | C19: COMPANY LIMITED | I19: franklin | J19: COMPANY, LIMITED. | AA19: =LEN(C19)+LEN(D19)+LEN(E19)+LEN(F19)+LEN(G19)+LEN(H19)+LEN(I19)+LEN(K19)+LEN(L19)+LEN(M19)+LEN(N19) -> 23
A20: myb50222 | B20: 1888 | C20: UNITED MAY LUNDY GOLD COMPANY LIMITED | D20: 730638.09 | I20: colorado | J20: The authorised capital is £150,000, in fully-paid shares of £1 each. Tho | O20: b | AA20: =LEN(C20)+LEN(D20)+LEN(E20)+LEN(F20)+LEN(G20)+LEN(H20)+LEN(I20)+LEN(K20)+LEN(L20)+LEN(M20)+LEN(N20) -> 56
A21: myb51339 | B21: 1888 | C21: WEST ARGENTINE GOLD COMPANY LIMITED | I21: cornwall | J21: £9o 13s. 5d. per ton, £0,709 9s. ; discounts from merchants, £18 4s. 10d., which with the Inlance | O21: b | AA21: =LEN(C21)+LEN(D21)+LEN(E21)+LEN(F21)+LEN(G21)+LEN(H21)+LEN(I21)+LEN(K21)+LEN(L21)+LEN(M21)+LEN(N21) -> 43
A22: myb54857 | B22: 1888 | C22: HOMESTEAD KOMATI GOLDFIELDS OF SOUTH | I22: sierra | J22: HOMESTEAD KOMATI GOLDFIELDS OF SOUTH | K22: gold | L22: homestead | M22: komati | N22: board | U22: b | V22: b | W22: b | X22: b | Y22: b | AA22: =LEN(C22)+LEN(D22)+LEN(E22)+LEN(F22)+LEN(G22)+LEN(H22)+LEN(I22)+LEN(K22)+LEN(L22)+LEN(M22)+LEN(N22) -> 66
A23: myb59106 | B23: 1889 | C23: ANGLO ASIATIC SYNDICATE LIMITED | I23: mexico | J23: The bullion produced during the year 18 7 realised £105,687 18s. 8 1., and for the first nine | O23: b | AA23: =LEN(C23)+LEN(D23)+LEN(E23)+LEN(F23)+LEN(G23)+LEN(H23)+LEN(I23)+LEN(K23)+LEN(L23)+LEN(M23)+LEN(N23) -> 37
A24: myb62668 | B24: 1889 | C24: CLONCURRY COPPER AND SMELTING COMPANY | I24: glasgow | J24: CLONCURRY COPPER AND SMELTHTG. | AA24: =LEN(C24)+LEN(D24)+LEN(E24)+LEN(F24)+LEN(G24)+LEN(H24)+LEN(I24)+LEN(K24)+LEN(L24)+LEN(M24)+LEN(N24) -> 44
A25: myb69619 | B25: 1889 | C25: AND PUBLIC WORKS SYNDICATE LIMITED | I25: brazil | J25: exploring mining properties, Ac., in Brazil and elsewhere. | O25: b | AA25: =LEN(C25)+LEN(D25)+LEN(E25)+LEN(F25)+LEN(G25)+LEN(H25)+LEN(I25)+LEN(K25)+LEN(L25)+LEN(M25)+LEN(N25) -> 40
A26: myb75402 | B26: 1889 | C26: QUEEN CHARLOTTE SOUND GOLD MINE LIMITED | I26: new zealand | J26: and this sample, not picked in any way and without any visible signs of gold, yielded, on assay | AA26: =LEN(C26)+LEN(D26)+LEN(E26)+LEN(F26)+LEN(G26)+LEN(H26)+LEN(I26)+LEN(K26)+LEN(L26)+LEN(M26)+LEN(N26) -> 50
A27: myb75700 | B27: 1889 | C27: REPUBLICAN MOUNTAIN SILVER MINES LIMITED | I27: georgetown | J27: vendor in fall payment for the property, and are not entitled to any dividend | AA27: =LEN(C27)+LEN(D27)+LEN(E27)+LEN(F27)+LEN(G27)+LEN(H27)+LEN(I27)+LEN(K27)+LEN(L27)+LEN(M27)+LEN(N27) -> 50
A28: myb85575 | B28: 1889 | C28: KANYA EXPLORATION COMPANY LIMITED | I28: s of territories | J28: covered by the grant ; and prospecting work, conducted under the supervision of Mr. A. 8. | U28: a/b | AA28: =LEN(C28)+LEN(D28)+LEN(E28)+LEN(F28)+LEN(G28)+LEN(H28)+LEN(I28)+LEN(K28)+LEN(L28)+LEN(M28)+LEN(N28) -> 49
A29: myb87517 | B29: 1889 | C29: MORGENZON GOLD MINING COMPANY LIMITED | I29: johannesburg | J29: No. 73, granted by the Government of the South African Republic for 15 years, | AA29: =LEN(C29)+LEN(D29)+LEN(E29)+LEN(F29)+LEN(G29)+LEN(H29)+LEN(I29)+LEN(K29)+LEN(L29)+LEN(M29)+LEN(N29) -> 49
A30: myb88079 | B30: 1889 | C30: NIGEL GOLD MINING COMPANY LIMITED | I30: heidelberg | J30: THIS company was formed in July, 1888, for the purpose of acquiring a mining | AA30: =LEN(C30)+LEN(D30)+LEN(E30)+LEN(F30)+LEN(G30)+LEN(H30)+LEN(I30)+LEN(K30)+LEN(L30)+LEN(M30)+LEN(N30) -> 43
A31: myb90530 | B31: 1889 | C31: MINING AND EXPLORATION CO LTD | I31: australia | J31: and £32,132 5s. paid up ; the 100 founders shares and 20,000 ordinary shares | AA31: =LEN(C31)+LEN(D31)+LEN(E31)+LEN(F31)+LEN(G31)+LEN(H31)+LEN(I31)+LEN(K31)+LEN(L31)+LEN(M31)+LEN(N31) -> 38
A32: myb93188 | B32: 1889 | C32: ZAMBESI CONCESSIONS COMPANY LIMITED | I32: london | J32: Directors. | AA32: =LEN(C32)+LEN(D32)+LEN(E32)+LEN(F32)+LEN(G32)+LEN(H32)+LEN(I32)+LEN(K32)+LEN(L32)+LEN(M32)+LEN(N32) -> 41
A33: myb95061 | B33: 1891 | C33: BAHANCANNE COPFEH | D33: NA | E33: NA | F33: NA | G33: NA | H33: NA | I33: NA | J33: is common and the fee 2s. 6d. per deed. | K33: NA | L33: NA | M33: NA | N33: NA | O33: a | Z33: 2 | AA33: =LEN(C33) -> 17
A34: myb97309 | B34: 1891 | C34: CENTRAL ARGENTINE GOLD FIELDS LIMITED | I34: florence | J34: Sarawak Coal Concession acquired in April, 1889 , which gives the right to mine for cos , | O34: b | U34: b | AA34: =LEN(C34)+LEN(D34)+LEN(E34)+LEN(F34)+LEN(G34)+LEN(H34)+LEN(I34)+LEN(K34)+LEN(L34)+LEN(M34)+LEN(N34) -> 45
A35: myb97977 | B35: 1891 | C35: UNION CORPORATION LTD | I35: somerset | J35: the proportion which the amount of capital subscribed bears to the nominal | O35: b | U35: b | AA35: =LEN(C35)+LEN(D35)+LEN(E35)+LEN(F35)+LEN(G35)+LEN(H35)+LEN(I35)+LEN(K35)+LEN(L35)+LEN(M35)+LEN(N35) -> 29
A36: myb100462 | B36: 1891 | C36: ENGLISH CROWN SPELTER COMPANY LIMITED | I36: swansea | J36: creation of 16,000 new shares of £1 each, and the £4 shares were sub-divided | AA36: =LEN(C36)+LEN(D36)+LEN(E36)+LEN(F36)+LEN(G36)+LEN(H36)+LEN(I36)+LEN(K36)+LEN(L36)+LEN(M36)+LEN(N36) -> 44
A37: myb103335 | B37: 1891 | C37: ISLE OF MAN MINING COMPANY LIMITED | J37: Beckwith e shaft has been sunk 17 fathoms, or deep enough for another level below the | AA37: =LEN(C37)+LEN(D37)+LEN(E37)+LEN(F37)+LEN(G37)+LEN(H37)+LEN(I37)+LEN(K37)+LEN(L37)+LEN(M37)+LEN(N37) -> 34
A38: myb107969 | B38: 1891 | C38: NEW MINERA MININ G | D38: NA | E38: NA | F38: NA | G38: NA | H38: NA | I38: lima | J38: 25th August and 9th September, 1890, to wind up the oompany voluntarily and | K38: NA | L38: NA | M38: NA | N38: NA | O38: a | U38: b | Z38: 2 | AA38: =LEN(C38) -> 18
A39: myb119202 | B39: 1891 | C39: SYNDICATE LIMITED | I39: london | J39: Directors. | AA39: =LEN(C39)+LEN(D39)+LEN(E39)+LEN(F39)+LEN(G39)+LEN(H39)+LEN(I39)+LEN(K39)+LEN(L39)+LEN(M39)+LEN(N39) -> 23
A40: myb123322 | B40: 1891 | C40: NORTH AFRICAN EXPLORATION SYNDICATE | I40: transvaal | J40: Offloes. | U40: b | AA40: =LEN(C40)+LEN(D40)+LEN(E40)+LEN(F40)+LEN(G40)+LEN(H40)+LEN(I40)+LEN(K40)+LEN(L40)+LEN(M40)+LEN(N40) -> 44
...

Sheet ammt
A1: id | B1: year | C1: company | D1: stock | E1: office | F1: yinc | G1: locinc | H1: loc | I1: text | J1: lastname | K1: firstname | L1: middlename | M1: prof | N1: company | O1: stock | P1: office | Q1: yinc | R1: locinc | S1: loc | T1: text | U1: lastname | V1: firstname | W1: middlename | X1: prof | Y1: cer | Z1: tot | AA1: extracted/actual | AB1: positive | AC1: negative
A2: amm218 | B2: 1907 | C2: Reynolds Alaska Development Company. Ellamar. | E2: State St, Boston | H2: boston | I2: Office, 27 State St., Boston. Howard D. Reynolds, Pres.; Blamey Stevens. | J2: reynolds | K2: howard | L2: d | M2: Pres | Z2: =LEN(C2)+LEN(D2)+LEN(E2)+LEN(F2)+LEN(G2)+LEN(H2)+LEN(J2)+LEN(K2)+LEN(L2)+LEN(M2) -> 87 | AA2: positive | AB2: t | AC2: f
A3: amm241 | B3: 1907 | C3: Yukon Consolidated Gold Fields Company. Dawson. | H3: broadway | I3: (Guggenheim Exploration Co.) Office, 71 Broadway, New York. Oscar | P3: b | Z3: =LEN(C3)+LEN(D3)+LEN(E3)+LEN(F3)+LEN(G3)+LEN(H3)+LEN(J3)+LEN(K3)+LEN(L3)+LEN(M3) -> 56 | AA3: negative | AB3: f | AC3: t
A4: amm296 | B4: 1907 | C4: Republic Zinc Company. Rush. | I4: Republic Zinc Company. Rush. | Z4: =LEN(C4)+LEN(D4)+LEN(E4)+LEN(F4)+LEN(G4)+LEN(H4)+LEN(J4)+LEN(K4)+LEN(L4)+LEN(M4) -> 28
A5: amm428 | B5: 1907 | C5: Black Prince Copper Company. Johnson. | I5: Teviston. | N5: b | Z5: =LEN(C5)+LEN(D5)+LEN(E5)+LEN(F5)+LEN(G5)+LEN(H5)+LEN(J5)+LEN(K5)+LEN(L5)+LEN(M5) -> 37 | AA5: code
A6: amm704 | B6: 1907 | C6: Henrietta Cyanide & Development Company. Big Bug, | I6: Prescott. | N6: b | Z6: =LEN(C6)+LEN(D6)+LEN(E6)+LEN(F6)+LEN(G6)+LEN(H6)+LEN(J6)+LEN(K6)+LEN(L6)+LEN(M6) -> 49 | AA6: extracted/actual | AB6: positive | AC6: negative
A7: amm1078 | B7: 1907 | C7: Union Pass Gold Mining Company. Kingman. | I7: United Globe Mines. Globe. | N7: b | Z7: =LEN(C7)+LEN(D7)+LEN(E7)+LEN(F7)+LEN(G7)+LEN(H7)+LEN(J7)+LEN(K7)+LEN(L7)+LEN(M7) -> 40 | AA7: positive | AC7: f
A8: amm1156 | B8: 1907 | C8: American Mining & Development Company. Kennett. | I8: American Mining & Development Company. Kennett. | Z8: =LEN(C8)+LEN(D8)+LEN(E8)+LEN(F8)+LEN(G8)+LEN(H8)+LEN(J8)+LEN(K8)+LEN(L8)+LEN(M8) -> 47 | AA8: negative | AB8: f
A9: amm1249 | B9: 1907 | C9: Bully Hill Copper Mining & Smelting Company. Winthrop. | I9: Bully Hill Copper Mining & Smelting Company. Winthrop. | Z9: =LEN(C9)+LEN(D9)+LEN(E9)+LEN(F9)+LEN(G9)+LEN(H9)+LEN(J9)+LEN(K9)+LEN(L9)+LEN(M9) -> 54
A10: amm1481 | B10: 1907 | C10: Empire Mines & Investment Company. Grass Valley. | I10: men. | Z10: =LEN(C10)+LEN(D10)+LEN(E10)+LEN(F10)+LEN(G10)+LEN(H10)+LEN(J10)+LEN(K10)+LEN(L10)+LEN(M10) -> 48 | AA10: types of mistakes on true positives
A11: amm1890 | B11: 1907 | C11: New Bodie Mining Company. Bodie. | I11: W. A. R. Loose, Mgr. Gold. Steam. 20 men. | J11: looal | K11: a | L11: r | M11: Mgr | U11: b | V11: b | W11: b | Z11: =LEN(C11)+LEN(D11)+LEN(E11)+LEN(F11)+LEN(G11)+LEN(H11)+LEN(J11)+LEN(K11)+LEN(L11)+LEN(M11) -> 42 | AA11: no mistake
A12: amm2198 | B12: 1907 | C12: Trojan Mining Company. Fenner. | I12: A. M. Rockwell. Supt. Bonanza King Mine. Silver, Lead & Zinc. Steam | J12: rochester | K12: a | M12: Supt | U12: b | W12: b | Z12: =LEN(C12)+LEN(D12)+LEN(E12)+LEN(F12)+LEN(G12)+LEN(H12)+LEN(J12)+LEN(K12)+LEN(L12)+LEN(M12) -> 44 | AA12: source to text | AB12: a
A13: amm2790 | B13: 1907 | C13: Gold Dollar Consolidated Mining Company. Victor. | I13: Newett. | N13: b | Z13: =LEN(C13)+LEN(D13)+LEN(E13)+LEN(F13)+LEN(G13)+LEN(H13)+LEN(J13)+LEN(K13)+LEN(L13)+LEN(M13) -> 48 | AA13: text to class | AB13: b
A14: amm2900 | B14: 1907 | C14: Home Run Leasing Company. | I14: Home Run Leasing Company. | Z14: =LEN(C14)+LEN(D14)+LEN(E14)+LEN(F14)+LEN(G14)+LEN(H14)+LEN(J14)+LEN(K14)+LEN(L14)+LEN(M14) -> 25
A15: amm2938 | B15: 1907 | C15: Indiana Gold Mining & Milling Company. Idaho Springs. | H15: indiana | I15: Indiana Gold Mining & Milling Company. Idaho Springs. | Z15: =LEN(C15)+LEN(D15)+LEN(E15)+LEN(F15)+LEN(G15)+LEN(H15)+LEN(J15)+LEN(K15)+LEN(L15)+LEN(M15) -> 61
A16: amm2955 | B16: 1907 | C16: Iron Silver Mining Company. Leadville. | I16: & Dome Mines. Gold, Silver, Lead & Zinc. Steam. 100 ton Concentrat | Z16: =LEN(C16)+LEN(D16)+LEN(E16)+LEN(F16)+LEN(G16)+LEN(H16)+LEN(J16)+LEN(K16)+LEN(L16)+LEN(M16) -> 38
A17: amm3598 | B17: 1907 | C17: Wonderful London Mines Company. Breckenridge. | H17: denver | I17: Wood (Henry E.) Ore Testing Works. 1734 Arapahoe St., Denver. | N17: b | Z17: =LEN(C17)+LEN(D17)+LEN(E17)+LEN(F17)+LEN(G17)+LEN(H17)+LEN(J17)+LEN(K17)+LEN(L17)+LEN(M17) -> 52
A18: amm3924 | B18: 1907 | C18: Greyhound Mining & Milling Company limited. | H18: custer | I18: Custer. | N18: b | Z18: =LEN(C18)+LEN(D18)+LEN(E18)+LEN(F18)+LEN(G18)+LEN(H18)+LEN(J18)+LEN(K18)+LEN(L18)+LEN(M18) -> 50
A19: amm4213 | B19: 1907 | C19: X Ray Mining Company. | I19: Pearl. | N19: b | Z19: =LEN(C19)+LEN(D19)+LEN(E19)+LEN(F19)+LEN(G19)+LEN(H19)+LEN(J19)+LEN(K19)+LEN(L19)+LEN(M19) -> 21
A20: amm4526 | B20: 1907 | C20: Consumers Ore Company. Palmer. J. R. Thompson, Gen. Mgr.; John H. Huhtala, Supt. Richmond Mine. | H20: michigan | I20: 118 MICHIGAN. | N20: b | S20: b | Z20: =LEN(C20)+LEN(D20)+LEN(E20)+LEN(F20)+LEN(G20)+LEN(H20)+LEN(J20)+LEN(K20)+LEN(L20)+LEN(M20) -> 104
A21: amm4545 | B21: 1907 | C21: Mineral Mining Company. Iron Mountain. | E21: Milwaukee, Wis | H21: milwaukee | I21: Office, Milwaukee, Wis. Elwin F. Brown, Gen. Mgr. Nanaimo, Breen, | J21: brown | K21: elwin | M21: Mgr | W21: b | Z21: =LEN(C21)+LEN(D21)+LEN(E21)+LEN(F21)+LEN(G21)+LEN(H21)+LEN(J21)+LEN(K21)+LEN(L21)+LEN(M21) -> 75
A22: amm4595 | B22: 1907 | C22: Verona Mining Company. Iron Mountain. | I22: Verona Mining Company. Iron Mountain. | Z22: =LEN(C22)+LEN(D22)+LEN(E22)+LEN(F22)+LEN(G22)+LEN(H22)+LEN(J22)+LEN(K22)+LEN(L22)+LEN(M22) -> 37
A23: amm4709 | B23: 1907 | C23: Mine La Motte Lead & Smelting Company. Mine La Motte. | I23: Supt.; S. S. Clarke, Metallurgist. Lead, Nickel, Copper & Cobalt. Steam. | J23: clarke | K23: susan | M23: Supt | W23: b | X23: b | Z23: =LEN(C23)+LEN(D23)+LEN(E23)+LEN(F23)+LEN(G23)+LEN(H23)+LEN(J23)+LEN(K23)+LEN(L23)+LEN(M23) -> 68
A24: amm5343 | B24: 1907 | C24: (Amalgamated Copper Company.) Charles W. Goodale, E. M., Mgr.; John | I24: & West Colusa Mines. Copper Sulphides; Gold & Silver. Steam & Elec | N24: b | Z24: =LEN(C24)+LEN(D24)+LEN(E24)+LEN(F24)+LEN(G24)+LEN(H24)+LEN(J24)+LEN(K24)+LEN(L24)+LEN(M24) -> 67
A25: amm5893 | B25: 1907 | C25: New Era Mining Company. Searchlight. | I25: New Era Mining Company. Searchlight. | Z25: =LEN(C25)+LEN(D25)+LEN(E25)+LEN(F25)+LEN(G25)+LEN(H25)+LEN(J25)+LEN(K25)+LEN(L25)+LEN(M25) -> 36
A26: amm5902 | B26: 1907 | C26: North Mountain Mining Company. Cherry Creek. | I26: Cyanide Plant. 25 men. | Z26: =LEN(C26)+LEN(D26)+LEN(E26)+LEN(F26)+LEN(G26)+LEN(H26)+LEN(J26)+LEN(K26)+LEN(L26)+LEN(M26) -> 44
A27: amm6462 | B27: 1907 | C27: American Goldfields Company. | E27: Marquette Bdg | H27: marquette | I27: Office, 1114 Marquette Bdg., Chicago. W. J | J27: shales | K27: w | L27: j | M27: Supt | U27: b | X27: b | Z27: =LEN(C27)+LEN(D27)+LEN(E27)+LEN(F27)+LEN(G27)+LEN(H27)+LEN(J27)+LEN(K27)+LEN(L27)+LEN(M27) -> 63
A28: amm6574 | B28: 1907 | C28: Eureka Mining Company. | I28: A. F. Nelson, Supt. Gold. Steam. | J28: neilsou | K28: a | L28: f | M28: Supt | U28: b | Z28: =LEN(C28)+LEN(D28)+LEN(E28)+LEN(F28)+LEN(G28)+LEN(H28)+LEN(J28)+LEN(K28)+LEN(L28)+LEN(M28) -> 35
A29: amm7137 | B29: 1907 | C29: Gemini-Godiva Consolidated Mining Company. Eureka. | I29: & Copper. Water & Steam. 100 men. | Z29: =LEN(C29)+LEN(D29)+LEN(E29)+LEN(F29)+LEN(G29)+LEN(H29)+LEN(J29)+LEN(K29)+LEN(L29)+LEN(M29) -> 50
A30: amm7616 | B30: 1907 | C30: Kennedy Mining Company. Platteville. | I30: W. Oberholzer, Supt. St. Paul Mine. Steam. 50 ton Concentrating Plant. | J30: oats | K30: wilhelm | L30: arno | M30: Supt | U30: b | W30: b | Z30: =LEN(C30)+LEN(D30)+LEN(E30)+LEN(F30)+LEN(G30)+LEN(H30)+LEN(J30)+LEN(K30)+LEN(L30)+LEN(M30) -> 55
A31: amm7813 | B31: 1907 | C31: Interstate Exploration Company. Endicott Bdg, St. Paul, Minn. | I31: 2*BAL0ERAS N°I232 | N31: b | Z31: =LEN(C31)+LEN(D31)+LEN(E31)+LEN(F31)+LEN(G31)+LEN(H31)+LEN(J31)+LEN(K31)+LEN(L31)+LEN(M31) -> 61
A32: amm7854 | B32: 1907 | C32: REFINING COMPANY | I32: : | N32: b | Z32: =LEN(C32)+LEN(D32)+LEN(E32)+LEN(F32)+LEN(G32)+LEN(H32)+LEN(J32)+LEN(K32)+LEN(L32)+LEN(M32) -> 16
A33: amm7973 | B33: 1907 | C33: American Smelting & Refining Company. Santa Eulalia. | E33: Broadway, New York | H33: broadway | I33: Office, 71 Broadway, New York. Thomas H. Mitchell, Supt. Sauto Do | J33: mitchell | K33: thomas | M33: Supt | W33: b | Z33: =LEN(C33)+LEN(D33)+LEN(E33)+LEN(F33)+LEN(G33)+LEN(H33)+LEN(J33)+LEN(K33)+LEN(L33)+LEN(M33) -> 97
A34: amm8045 | B34: 1907 | C34: Clarinas Mining Company. Santa Barbara. | I34: & | N34: b | Z34: =LEN(C34)+LEN(D34)+LEN(E34)+LEN(F34)+LEN(G34)+LEN(H34)+LEN(J34)+LEN(K34)+LEN(L34)+LEN(M34) -> 39
A35: amm8104 | B35: 1907 | C35: Clarinas Mining Company. Santa Barbara. | I35: & | N35: b | Z35: =LEN(C35)+LEN(D35)+LEN(E35)+LEN(F35)+LEN(G35)+LEN(H35)+LEN(J35)+LEN(K35)+LEN(L35)+LEN(M35) -> 39
A36: amm8154 | B36: 1907 | C36: Grenadena Mining Company. Santa Barbara. | I36: Grenadena Mining Company. Santa Barbara. | Z36: =LEN(C36)+LEN(D36)+LEN(E36)+LEN(F36)+LEN(G36)+LEN(H36)+LEN(J36)+LEN(K36)+LEN(L36)+LEN(M36) -> 40
A37: amm8366 | B37: 1907 | C37: Coahuila Mining & Smelting Company. Viesca. | I37: Ragaz, Gen. Supt. of Mines; Ernest Harms, Metallurgist & Gen. Supt. of | J37: harman | K37: ernest | M37: Gen. Supt | N37: b | U37: b | Z37: =LEN(C37)+LEN(D37)+LEN(E37)+LEN(F37)+LEN(G37)+LEN(H37)+LEN(J37)+LEN(K37)+LEN(L37)+LEN(M37) -> 64
A38: amm8615 | B38: 1907 | C38: Mina Grande Mining & Milling Company. Tepehuanes. | I38: Eliseo C. Julio, Mgr. Silver & Gold. Steam. 100 men. | J38: judkewitsch | K38: eliseo | L38: c | M38: Mgr | N38: b | U38: b | Z38: =LEN(C38)+LEN(D38)+LEN(E38)+LEN(F38)+LEN(G38)+LEN(H38)+LEN(J38)+LEN(K38)+LEN(L38)+LEN(M38) -> 70
A39: amm8990 | B39: 1907 | C39: Bolanos Mining Company. Bolanos. | I39: Bolanos Mining Company. Bolanos. | Z39: =LEN(C39)+LEN(D39)+LEN(E39)+LEN(F39)+LEN(G39)+LEN(H39)+LEN(J39)+LEN(K39)+LEN(L39)+LEN(M39) -> 32
A40: amm9061 | B40: 1907 | C40: La Fortuna Mining Company. Ahualulco. | I40: La Fortuna Mining Company. Ahualulco. | Z40: =LEN(C40)+LEN(D40)+LEN(E40)+LEN(F40)+LEN(G40)+LEN(H40)+LEN(J40)+LEN(K40)+LEN(L40)+LEN(M40) -> 37
...

Sheet mmmt
A1: id | B1: year | C1: text | D1: company | E1: capital | F1: minerals | G1: owns | H1: owned | I1: doutput | J1: technology | K1: incor | L1: loc | M1: lastname | N1: firstname | O1: middlename | P1: prof | Q1: company | R1: capital | S1: minerals | T1: owns | U1: owned | V1: doutput | W1: technology | X1: incor | Y1: loc | Z1: text | AA1: lastname | AB1: firstname | AC1: middlename | AD1: prof | AE1: cer | AF1: tot | AH1: extracted/actual | AI1: positive | AJ1: negative
A2: mmm5 | B2: 1926 | C2: po, asientso ags, | D2: aguascalientes metal co. | L2: asientso ags | Y2: a | AE2: 1 | AF2: =LEN(D2)+LEN(E2)+LEN(F2)+LEN(G2)+LEN(H2)+LEN(I2)+LEN(J2)+LEN(K2)+LEN(L2)+LEN(M2)+LEN(N2)+LEN(O2)+LEN(P2) -> 36 | AH2: positive | AI2: t | AJ2: f
A3: mmm15 | B3: 1926 | C3: 200000 | D3: cia min la fortuna sa | E3: 96665.056 | L3: aguascalientes | AF3: =LEN(D3)+LEN(E3)+LEN(F3)+LEN(G3)+LEN(H3)+LEN(I3)+LEN(J3)+LEN(K3)+LEN(L3)+LEN(M3)+LEN(N3)+LEN(O3)+LEN(P3) -> 45 | AH3: negative | AI3: f | AJ3: t
A4: mmm21 | B4: 1926 | C4: 212 725 | D4: compania minera san geronimo sa | L4: aguascalientes | R4: b | AF4: =LEN(D4)+LEN(E4)+LEN(F4)+LEN(G4)+LEN(H4)+LEN(I4)+LEN(J4)+LEN(K4)+LEN(L4)+LEN(M4)+LEN(N4)+LEN(O4)+LEN(P4) -> 45
A5: mmm24 | B5: 1926 | C5: copper silver | D5: compania minera san geronimo sa | F5: copper silver | L5: aguascalientes | AF5: =LEN(D5)+LEN(E5)+LEN(F5)+LEN(G5)+LEN(H5)+LEN(I5)+LEN(J5)+LEN(K5)+LEN(L5)+LEN(M5)+LEN(N5)+LEN(O5)+LEN(P5) -> 58 | AH5: code
A6: mmm31 | B6: 1926 | C6: location& po, asientos, ags, | D6: compania min socorro y an sa | L6: asientos ags | AF6: =LEN(D6)+LEN(E6)+LEN(F6)+LEN(G6)+LEN(H6)+LEN(I6)+LEN(J6)+LEN(K6)+LEN(L6)+LEN(M6)+LEN(N6)+LEN(O6)+LEN(P6) -> 40 | AH6: extracted/actual | AI6: positive | AJ6: negative
A7: mmm33 | B7: 1926 | C7: 2800 | D7: compania min socorro y an sa | E7: 1353.3108 | L7: aguascalientes | Q7: b | AF7: =LEN(D7)+LEN(E7)+LEN(F7)+LEN(G7)+LEN(H7)+LEN(I7)+LEN(J7)+LEN(K7)+LEN(L7)+LEN(M7)+LEN(N7)+LEN(O7)+LEN(P7) -> 54 | AH7: positive | AJ7: f
A8: mmm42 | B8: 1926 | C8: daily out put, 300 metric tons., | D8: minerva mining co. s. a. | I8: 300 metric tons. | L8: aguascalientes | AF8: =LEN(D8)+LEN(E8)+LEN(F8)+LEN(G8)+LEN(H8)+LEN(I8)+LEN(J8)+LEN(K8)+LEN(L8)+LEN(M8)+LEN(N8)+LEN(O8)+LEN(P8) -> 54 | AH8: negative | AI8: f
A9: mmm50 | B9: 1926 | C9: spt of power, .j. kaufer, asientos, ags. | D9: minerva mining co. s. a. | L9: asientos ags | M9: kasper | P9: spt of power | AA9: b | AB9: b | AF9: =LEN(D9)+LEN(E9)+LEN(F9)+LEN(G9)+LEN(H9)+LEN(I9)+LEN(J9)+LEN(K9)+LEN(L9)+LEN(M9)+LEN(N9)+LEN(O9)+LEN(P9) -> 54
A10: mmm56 | B10: 1926 | C10: mexico city office, a.venida capuchinas 44, manager., mr l majar | D10: compañia del boleo | L10: mr l majar | Y10: b | AA10: b | AB10: b | AD10: b | AF10: =LEN(D10)+LEN(E10)+LEN(F10)+LEN(G10)+LEN(H10)+LEN(I10)+LEN(J10)+LEN(K10)+LEN(L10)+LEN(M10)+LEN(N10)+LEN(O10)+LEN(P10) -> 28 | AH10: types of mistakes on true positives
A11: mmm57 | B11: 1926 | C11: copper | D11: compañia del boleo | F11: copper | L11: baja california. | AF11: =LEN(D11)+LEN(E11)+LEN(F11)+LEN(G11)+LEN(H11)+LEN(I11)+LEN(J11)+LEN(K11)+LEN(L11)+LEN(M11)+LEN(N11)+LEN(O11)+LEN(P11) -> 40 | AH11: no mistake
A12: mmm61 | B12: 1926 | C12: refining plant location, sta. rosalia, b · c ·, | D12: compañia del boleo | L12: sta rosalia bc | AF12: =LEN(D12)+LEN(E12)+LEN(F12)+LEN(G12)+LEN(H12)+LEN(I12)+LEN(J12)+LEN(K12)+LEN(L12)+LEN(M12)+LEN(N12)+LEN(O12)+LEN(P12) -> 32 | AH12: source to text | AI12: a
A13: mmm61 | B13: 1926 | C13: refining plant location, sta. rosalia, b · c ·, | D13: compañia del boleo | L13: sta rosalia bc | AF13: =LEN(D13)+LEN(E13)+LEN(F13)+LEN(G13)+LEN(H13)+LEN(I13)+LEN(J13)+LEN(K13)+LEN(L13)+LEN(M13)+LEN(N13)+LEN(O13)+LEN(P13) -> 32 | AH13: text to source | AI13: b
A14: mmm68 | B14: 1926 | C14: ming. Eng., .j. cazanove., sta. ro salia, b. c. | D14: compañia del boleo | L14: ro salia bc | Y14: a | AA14: b | AB14: b | AD14: b | AE14: 1 | AF14: =LEN(D14)+LEN(E14)+LEN(F14)+LEN(G14)+LEN(H14)+LEN(I14)+LEN(J14)+LEN(K14)+LEN(L14)+LEN(M14)+LEN(N14)+LEN(O14)+LEN(P14) -> 29
A15: mmm75 | B15: 1926 | C15: foreign office, 40 w. congress st. tucson, ariz., | D15: cia y reduccion del golfo s. a. | L15: st tucson ariz | AF15: =LEN(D15)+LEN(E15)+LEN(F15)+LEN(G15)+LEN(H15)+LEN(I15)+LEN(J15)+LEN(K15)+LEN(L15)+LEN(M15)+LEN(N15)+LEN(O15)+LEN(P15) -> 45
A16: mmm76 | B16: 1926 | C16: silver gold arsenic. | D16: cia y reduccion del golfo s. a. | F16: silver gold arsenic. | L16: baja california. | AF16: =LEN(D16)+LEN(E16)+LEN(F16)+LEN(G16)+LEN(H16)+LEN(I16)+LEN(J16)+LEN(K16)+LEN(L16)+LEN(M16)+LEN(N16)+LEN(O16)+LEN(P16) -> 67
A17: mmm78 | B17: 1926 | C17: grl. spt., geo. w. pickett, san antonio, b. c. | D17: cia y reduccion del golfo s. a. | L17: san antonio bc | M17: pickard | N17: geo | P17: grl. spt. | AA17: b | AC17: b | AF17: =LEN(D17)+LEN(E17)+LEN(F17)+LEN(G17)+LEN(H17)+LEN(I17)+LEN(J17)+LEN(K17)+LEN(L17)+LEN(M17)+LEN(N17)+LEN(O17)+LEN(P17) -> 64
A18: mmm84 | B18: 1926 | C18: lead zinc silver. | D18: calera mining co. | F18: lead zinc silver. | L18: chihuahua | AF18: =LEN(D18)+LEN(E18)+LEN(F18)+LEN(G18)+LEN(H18)+LEN(I18)+LEN(J18)+LEN(K18)+LEN(L18)+LEN(M18)+LEN(N18)+LEN(O18)+LEN(P18) -> 43
A19: mmm84 | B19: 1926 | C19: lead zinc silver. | D19: calera mining co. | F19: lead zinc silver. | L19: chihuahua | AF19: =LEN(D19)+LEN(E19)+LEN(F19)+LEN(G19)+LEN(H19)+LEN(I19)+LEN(J19)+LEN(K19)+LEN(L19)+LEN(M19)+LEN(N19)+LEN(O19)+LEN(P19) -> 43
A20: mmm91 | B20: 1926 | C20: asst. grl. mgr., e. s. plumb, chihuahua, chih. | D20: calera mining co. | L20: chihuahua chih | M20: plews | N20: edwanl | P20: asst. grl. mgr. | AA20: b | AC20: b | AF20: =LEN(D20)+LEN(E20)+LEN(F20)+LEN(G20)+LEN(H20)+LEN(I20)+LEN(J20)+LEN(K20)+LEN(L20)+LEN(M20)+LEN(N20)+LEN(O20)+LEN(P20) -> 57
A21: mmm100 | B21: 1926 | C21: location, & p. o., chihuahua, chih. | D21: cia . minera alianza | L21: chihuahua chih | AF21: =LEN(D21)+LEN(E21)+LEN(F21)+LEN(G21)+LEN(H21)+LEN(I21)+LEN(J21)+LEN(K21)+LEN(L21)+LEN(M21)+LEN(N21)+LEN(O21)+LEN(P21) -> 34
A22: mmm102 | B22: 1926 | C22: manager, a. l. kraft, chihuahua, chih. | D22: cia . minera alianza | L22: chihuahua chih | M22: kothsctaild | N22: a | O22: h | P22: manager | AA22: b | AC22: b | AF22: =LEN(D22)+LEN(E22)+LEN(F22)+LEN(G22)+LEN(H22)+LEN(I22)+LEN(J22)+LEN(K22)+LEN(L22)+LEN(M22)+LEN(N22)+LEN(O22)+LEN(P22) -> 54
A23: mmm108 | B23: 1926 | C23: owners, the prieto estate., | D23: cia. Minera astreas y otros | L23: chihuahua | AF23: =LEN(D23)+LEN(E23)+LEN(F23)+LEN(G23)+LEN(H23)+LEN(I23)+LEN(J23)+LEN(K23)+LEN(L23)+LEN(M23)+LEN(N23)+LEN(O23)+LEN(P23) -> 36
A24: mmm116 | B24: 1926 | C24: cyanidation., | D24: cia. Minera cienega sa | J24: cyanidation. | L24: chihuahua | AF24: =LEN(D24)+LEN(E24)+LEN(F24)+LEN(G24)+LEN(H24)+LEN(I24)+LEN(J24)+LEN(K24)+LEN(L24)+LEN(M24)+LEN(N24)+LEN(O24)+LEN(P24) -> 43
A25: mmm117 | B25: 1926 | C25: daily output, 50 metric tons., | D25: cia. Minera cienega sa | I25: 50 metric tons. | L25: chihuahua | AF25: =LEN(D25)+LEN(E25)+LEN(F25)+LEN(G25)+LEN(H25)+LEN(I25)+LEN(J25)+LEN(K25)+LEN(L25)+LEN(M25)+LEN(N25)+LEN(O25)+LEN(P25) -> 46
A26: mmm120 | B26: 1926 | C26: purch. agt., clyde harding, el paso, texas. | D26: cia. Minera cienega sa | L26: el paso texas | M26: hardenbergh | N26: clyde | P26: purch. agt. | AA26: b | AF26: =LEN(D26)+LEN(E26)+LEN(F26)+LEN(G26)+LEN(H26)+LEN(I26)+LEN(J26)+LEN(K26)+LEN(L26)+LEN(M26)+LEN(N26)+LEN(O26)+LEN(P26) -> 62
A27: mmm124 | B27: 1926 | C27: this company owns the leponte y an. mines. | D27: cia. minera de naica | G27: this company owns the leponte y an. mines. | L27: chihuahua | AF27: =LEN(D27)+LEN(E27)+LEN(F27)+LEN(G27)+LEN(H27)+LEN(I27)+LEN(J27)+LEN(K27)+LEN(L27)+LEN(M27)+LEN(N27)+LEN(O27)+LEN(P27) -> 71
A28: mmm147 | B28: 1926 | C28: foreign office, warren, ariz., | D28: cia . min . erupcion y an. s. a. | L28: office warren ariz | Y28: b | AF28: =LEN(D28)+LEN(E28)+LEN(F28)+LEN(G28)+LEN(H28)+LEN(I28)+LEN(J28)+LEN(K28)+LEN(L28)+LEN(M28)+LEN(N28)+LEN(O28)+LEN(P28) -> 50
A29: mmm148 | B29: 1926 | C29: lead silver. | D29: cia . min . erupcion y an. s. a. | F29: lead silver. | L29: chihuahua | AF29: =LEN(D29)+LEN(E29)+LEN(F29)+LEN(G29)+LEN(H29)+LEN(I29)+LEN(J29)+LEN(K29)+LEN(L29)+LEN(M29)+LEN(N29)+LEN(O29)+LEN(P29) -> 53
A30: mmm148 | B30: 1926 | C30: this company is subsidiary of ahumada lead co. | D30: cia . min . erupcion y an. s. a. | G30: this company is subsidiary of ahumada lead co. | L30: chihuahua | T30: b | U30: b | AF30: =LEN(D30)+LEN(E30)+LEN(F30)+LEN(G30)+LEN(H30)+LEN(I30)+LEN(J30)+LEN(K30)+LEN(L30)+LEN(M30)+LEN(N30)+LEN(O30)+LEN(P30) -> 87
A31: mmm151 | B31: 1926 | C31: purch. Agt., john b. rawlings, 315 two republics bdg., el paso. texas. | D31: cia . min . erupcion y an. s. a. | L31: el paso texas | M31: raub | N31: john | P31: purch. Agt. | AA31: b | AC31: b | AF31: =LEN(D31)+LEN(E31)+LEN(F31)+LEN(G31)+LEN(H31)+LEN(I31)+LEN(J31)+LEN(K31)+LEN(L31)+LEN(M31)+LEN(N31)+LEN(O31)+LEN(P31) -> 64
A32: mmm155 | B32: 1926 | C32: manager, jose bovio, chihuahua, chih | D32: cia. min. la sorpresa y an. s. a. | L32: chihuahua chih | M32: bovill | N32: jose | P32: manager | AA32: b | AF32: =LEN(D32)+LEN(E32)+LEN(F32)+LEN(G32)+LEN(H32)+LEN(I32)+LEN(J32)+LEN(K32)+LEN(L32)+LEN(M32)+LEN(N32)+LEN(O32)+LEN(P32) -> 64
A33: mmm158 | B33: 1926 | C33: manager, j. c. shepard, chihuahua, chih. | D33: cia. min. mexicana de la cieneguilla | L33: chihuahua chih | M33: shepard | N33: j | P33: manager | AC33: b | AF33: =LEN(D33)+LEN(E33)+LEN(F33)+LEN(G33)+LEN(H33)+LEN(I33)+LEN(J33)+LEN(K33)+LEN(L33)+LEN(M33)+LEN(N33)+LEN(O33)+LEN(P33) -> 65
A34: mmm161 | B34: 1926 | C34: this conmpany owns the san pascual mines . | D34: cia. Min. san pascual de las adargas s. a. | G34: this conmpany owns the san pascual mines . | L34: chihuahua | AF34: =LEN(D34)+LEN(E34)+LEN(F34)+LEN(G34)+LEN(H34)+LEN(I34)+LEN(J34)+LEN(K34)+LEN(L34)+LEN(M34)+LEN(N34)+LEN(O34)+LEN(P34) -> 93
A35: mmm161 | B35: 1926 | C35: lead silver gold. | D35: cia. Min. san pascual de las adargas s. a. | F35: lead silver gold. | L35: chihuahua | AF35: =LEN(D35)+LEN(E35)+LEN(F35)+LEN(G35)+LEN(H35)+LEN(I35)+LEN(J35)+LEN(K35)+LEN(L35)+LEN(M35)+LEN(N35)+LEN(O35)+LEN(P35) -> 68
A36: mmm161 | B36: 1926 | C36: this conmpany owns the san pascual mines . | D36: cia. Min. san pascual de las adargas s. a. | G36: this conmpany owns the san pascual mines . | L36: chihuahua | AF36: =LEN(D36)+LEN(E36)+LEN(F36)+LEN(G36)+LEN(H36)+LEN(I36)+LEN(J36)+LEN(K36)+LEN(L36)+LEN(M36)+LEN(N36)+LEN(O36)+LEN(P36) -> 93
A37: mmm172 | B37: 1926 | C37: gold silver. | D37: dolores mines co. | F37: gold silver. | L37: chihuahua | AF37: =LEN(D37)+LEN(E37)+LEN(F37)+LEN(G37)+LEN(H37)+LEN(I37)+LEN(J37)+LEN(K37)+LEN(L37)+LEN(M37)+LEN(N37)+LEN(O37)+LEN(P37) -> 38
A38: mmm174 | B38: 1926 | C38: daily output, 200 metric tons, | D38: dolores mines co. | I38: 200 metric tons | L38: chihuahua | AF38: =LEN(D38)+LEN(E38)+LEN(F38)+LEN(G38)+LEN(H38)+LEN(I38)+LEN(J38)+LEN(K38)+LEN(L38)+LEN(M38)+LEN(N38)+LEN(O38)+LEN(P38) -> 41
A39: mmm177 | B39: 1926 | C39: grl. Mgr., f. m. estes, la dura, son. | D39: dolores mines co. | L39: la dura son | M39: estates | N39: francis | P39: grl. Mgr. | AA39: b | AC39: b | AF39: =LEN(D39)+LEN(E39)+LEN(F39)+LEN(G39)+LEN(H39)+LEN(I39)+LEN(J39)+LEN(K39)+LEN(L39)+LEN(M39)+LEN(N39)+LEN(O39)+LEN(P39) -> 51
A40: mmm186 | B40: 1926 | C40: foreign office, 780 fifth ave. new york, | D40: el potosi mining co. | L40: ave new york | Y40: b | AF40: =LEN(D40)+LEN(E40)+LEN(F40)+LEN(G40)+LEN(H40)+LEN(I40)+LEN(J40)+LEN(K40)+LEN(L40)+LEN(M40)+LEN(N40)+LEN(O40)+LEN(P40) -> 32
...

Sheet alumnit
A1: id | B1: source | C1: year | D1: lastname | E1: firstname | F1: middlename | G1: prof | H1: org | I1: loc | J1: year | K1: lastname | L1: firstname | M1: middlename | N1: prof | O1: org | P1: loc | Q1: cer | R1: tot | T1: extracted/actual | U1: positive | V1: negative
A2: co21472 | B2: colmines | C2: 1898 | D2: hill | E2: w | F2: h | G2: student | H2: colmines | I2: NA | P2: 1 | R2: =LEN(C2)+LEN(D2)+LEN(E2)+LEN(F2)+LEN(G2)+LEN(H2) -> 25 | T2: positive | U2: t | V2: f
A3: co34769 | B3: colmines | C3: 1905 | D3: patterson | E3: a | F3: w | G3: student | H3: colmines | I3: NA | P3: 1 | R3: =LEN(C3)+LEN(D3)+LEN(E3)+LEN(F3)+LEN(G3)+LEN(H3) -> 30 | T3: negative | U3: f | V3: t
A4: co48041 | B4: colmines | C4: 1902 | D4: wells | E4: f | F4: o | G4: student | H4: colmines | I4: NA | P4: 1 | R4: =LEN(C4)+LEN(D4)+LEN(E4)+LEN(F4)+LEN(G4)+LEN(H4) -> 26
A5: cu12925 | B5: cu | C5: 1892 | D5: drasel | E5: c | G5: student | H5: cu | I5: ny city | R5: =LEN(C5)+LEN(D5)+LEN(E5)+LEN(F5)+LEN(G5)+LEN(H5) -> 20 | T5: code
A6: cu16012 | B6: cu | C6: 1911 | D6: frank | E6: earle | G6: student | H6: cu | I6: ny city | J6: b | R6: =LEN(C6)+LEN(D6)+LEN(E6)+LEN(F6)+LEN(G6)+LEN(H6) -> 23 | T6: extracted/actual | U6: positive | V6: negative
A7: cu18812 | B7: cu | C7: 1907 | D7: guinchard | E7: a | G7: student | H7: cu | I7: ny city | R7: =LEN(C7)+LEN(D7)+LEN(E7)+LEN(F7)+LEN(G7)+LEN(H7) -> 23 | T7: positive | V7: f
A8: cu19207 | B8: cu | C8: 1898 | D8: hall | E8: harry | G8: student | H8: cu | I8: ny city | M8: b | R8: =LEN(C8)+LEN(D8)+LEN(E8)+LEN(F8)+LEN(G8)+LEN(H8) -> 22 | T8: negative | U8: f
A9: cu20488 | B9: cu | C9: 1892 | D9: hay | E9: a | G9: student | H9: cu | I9: ny city | R9: =LEN(C9)+LEN(D9)+LEN(E9)+LEN(F9)+LEN(G9)+LEN(H9) -> 17
A10: cu21124 | B10: cu | C10: 1911 | D10: herter | E10: a | F10: h | G10: student | H10: cu | I10: ny city | R10: =LEN(C10)+LEN(D10)+LEN(E10)+LEN(F10)+LEN(G10)+LEN(H10) -> 21 | T10: types of mistakes on true positives
A11: cu21791 | B11: cu | C11: 1885 | D11: hoffbauer | E11: o | G11: student | H11: cu | I11: ny city | M11: b | R11: =LEN(C11)+LEN(D11)+LEN(E11)+LEN(F11)+LEN(G11)+LEN(H11) -> 23 | T11: no mistake
A12: cu22577 | B12: cu | C12: 1904 | D12: howe | E12: a | F12: a | G12: student | H12: cu | I12: ny city | M12: b | R12: =LEN(C12)+LEN(D12)+LEN(E12)+LEN(F12)+LEN(G12)+LEN(H12) -> 19 | T12: source to text | U12: a
A13: cu23330 | B13: cu | C13: 1909 | D13: hutchinson | E13: george | F13: e | G13: student | H13: cu | I13: ny city | R13: =LEN(C13)+LEN(D13)+LEN(E13)+LEN(F13)+LEN(G13)+LEN(H13) -> 30 | T13: text to source | U13: b
A14: cu26219 | B14: cu | C14: 1884 | D14: lamb | E14: augustus | F14: j | G14: student | H14: cu | I14: ny city | R14: =LEN(C14)+LEN(D14)+LEN(E14)+LEN(F14)+LEN(G14)+LEN(H14) -> 26
A15: cu28529 | B15: cu | C15: 1912 | D15: macdermott | E15: s | F15: s | G15: student | H15: cu | I15: ny city | R15: =LEN(C15)+LEN(D15)+LEN(E15)+LEN(F15)+LEN(G15)+LEN(H15) -> 25
A16: cu29080 | B16: cu | C16: 1885 | D16: mannheim | E16: paul | F16: a | G16: student | H16: cu | I16: ny city | R16: =LEN(C16)+LEN(D16)+LEN(E16)+LEN(F16)+LEN(G16)+LEN(H16) -> 26
A17: cu31533 | B17: cu | C17: 1912 | D17: moffett | E17: h | G17: student | H17: cu | I17: ny city | M17: b | R17: =LEN(C17)+LEN(D17)+LEN(E17)+LEN(F17)+LEN(G17)+LEN(H17) -> 21
A18: cu36129 | B18: cu | C18: 1906 | D18: popper | E18: e | G18: student | H18: cu | I18: ny city | R18: =LEN(C18)+LEN(D18)+LEN(E18)+LEN(F18)+LEN(G18)+LEN(H18) -> 20
A19: cu37053 | B19: cu | C19: 1910 | D19: raphael | E19: a | G19: student | H19: cu | I19: ny city | M19: b | R19: =LEN(C19)+LEN(D19)+LEN(E19)+LEN(F19)+LEN(G19)+LEN(H19) -> 21
A20: cu44627 | B20: cu | C20: 1894 | D20: taylor | E20: o | G20: student | H20: cu | I20: ny city | L20: b | R20: =LEN(C20)+LEN(D20)+LEN(E20)+LEN(F20)+LEN(G20)+LEN(H20) -> 20
A21: cu46393 | B21: cu | C21: 1912 | D21: van | E21: t | G21: student | H21: cu | I21: ny city | K21: b | M21: b | R21: =LEN(C21)+LEN(D21)+LEN(E21)+LEN(F21)+LEN(G21)+LEN(H21) -> 17
A22: cu5040 | B22: cu | C22: 1902 | D22: brcneman | E22: h | F22: c | G22: student | H22: cu | I22: ny city | K22: a | Q22: 1 | R22: =LEN(C22)+LEN(D22)+LEN(E22)+LEN(F22)+LEN(G22)+LEN(H22) -> 23
A23: cu5940 | B23: cu | C23: 1884 | D23: bryce | E23: w | G23: student | H23: cu | I23: ny city | R23: =LEN(C23)+LEN(D23)+LEN(E23)+LEN(F23)+LEN(G23)+LEN(H23) -> 19
A24: cu6025 | B24: cu | C24: 1903 | D24: buckmaster | E24: f | F24: c | G24: student | H24: cu | I24: ny city | R24: =LEN(C24)+LEN(D24)+LEN(E24)+LEN(F24)+LEN(G24)+LEN(H24) -> 25
A25: cu7529 | B25: cu | C25: 1892 | D25: casamajor | E25: g | F25: h | G25: student | H25: cu | I25: ny city | R25: =LEN(C25)+LEN(D25)+LEN(E25)+LEN(F25)+LEN(G25)+LEN(H25) -> 24
A26: cu7564 | B26: cu | C26: 1893 | D26: caspe | E26: a | G26: student | H26: cu | I26: ny city | R26: =LEN(C26)+LEN(D26)+LEN(E26)+LEN(F26)+LEN(G26)+LEN(H26) -> 19
A27: cu8314 | B27: cu | C27: 1906 | D27: church | E27: j | F27: a | G27: student | H27: cu | I27: ny city | R27: =LEN(C27)+LEN(D27)+LEN(E27)+LEN(F27)+LEN(G27)+LEN(H27) -> 21
A28: en34067 | B28: eni | C28: 1905 | D28: ostos | E28: j | G28: student | H28: eni | I28: mexico city | J28: b | R28: =LEN(C28)+LEN(D28)+LEN(E28)+LEN(F28)+LEN(G28)+LEN(H28) -> 20
A29: en34315 | B29: eni | C29: 1905 | D29: palacio | E29: r | G29: student | H29: eni | I29: mexico city | J29: b | R29: =LEN(C29)+LEN(D29)+LEN(E29)+LEN(F29)+LEN(G29)+LEN(H29) -> 22
A30: en46554 | B30: eni | C30: 1905 | D30: vazquez | E30: s | G30: student | H30: eni | I30: mexico city | J30: b | R30: =LEN(C30)+LEN(D30)+LEN(E30)+LEN(F30)+LEN(G30)+LEN(H30) -> 22
A31: fr2471 | B31: frei | C31: 1865 | D31: de crano | E31: e | I31: san francisco usa | J31: b | M31: b | N31: b | O31: b | R31: =LEN(C31)+LEN(D31)+LEN(E31)+LEN(F31)+LEN(G31)+LEN(H31) -> 13
A32: fr2510 | B32: frei | C32: 1871 | D32: dietze | E32: georg | F32: moritz | I32: freiberg sachsen | J32: ?b | N32: b | O32: b | R32: =LEN(C32)+LEN(D32)+LEN(E32)+LEN(F32)+LEN(G32)+LEN(H32) -> 21
A33: fr2638 | B33: frei | C33: 1871 | D33: lowe | E33: francis | F33: asbury | G33: student | H33: freiberg school | I33: washington usa | R33: =LEN(C33)+LEN(D33)+LEN(E33)+LEN(F33)+LEN(G33)+LEN(H33) -> 43
A34: fr2697 | B34: frei | C34: 1871 | D34: zoric | E34: svetosar | G34: student | H34: freiberg school | I34: titel ungarn | J34: b | R34: =LEN(C34)+LEN(D34)+LEN(E34)+LEN(F34)+LEN(G34)+LEN(H34) -> 39
A35: fr2732 | B35: frei | C35: 1873 | D35: stoiber | E35: eduard | F35: georg | G35: student | H35: freiberg school | I35: new york usa | R35: =LEN(C35)+LEN(D35)+LEN(E35)+LEN(F35)+LEN(G35)+LEN(H35) -> 44
A36: fr2813 | B36: frei | C36: 1874 | D36: heck | E36: carl | I36: dierdorf rheinpreuben | J36: b | N36: b | O36: b | R36: =LEN(C36)+LEN(D36)+LEN(E36)+LEN(F36)+LEN(G36)+LEN(H36) -> 12
A37: fr2955 | B37: frei | C37: 1876 | D37: fuch8 | E37: ernst | F37: fiirchtegott | I37: chemnitz sachsen | J37: b | K37: a | M37: a | N37: b | O37: b | Q37: 3 | R37: =LEN(C37)+LEN(D37)+LEN(E37)+LEN(F37)+LEN(G37)+LEN(H37) -> 26
A38: fr2987 | B38: frei | C38: 1877 | D38: wei8 | E38: carl | F38: eduard | G38: student | H38: freiberg school | I38: marienberg | K38: a | Q38: 1 | R38: =LEN(C38)+LEN(D38)+LEN(E38)+LEN(F38)+LEN(G38)+LEN(H38) -> 40
A39: fr2988 | B39: frei | C39: 1876 | D39: zetzsche | E39: heinrich | F39: paul | I39: altenburg | N39: b | O39: b | R39: =LEN(C39)+LEN(D39)+LEN(E39)+LEN(F39)+LEN(G39)+LEN(H39) -> 24
A40: fr3001 | B40: frei | C40: 1883 | D40: fischer | E40: heinrich | F40: carl | G40: student | H40: freiberg school | I40: colditz sachsen | R40: =LEN(C40)+LEN(D40)+LEN(E40)+LEN(F40)+LEN(G40)+LEN(H40) -> 45
...

Sheet aime
A1: id | B1: year | C1: simpname | D1: nationality | E1: edu | F1: prof | G1: org | H1: loc | I1: simpname | J1: nationality | K1: edu | L1: prof | M1: org | N1: loc | O1: cer | P1: tot | R1: extracted/actual | S1: positive | T1: negative
A2: tai83 | B2: 1873 | C2: faber, d | H2: new york city | I2: b | P2: =LEN(C2)+LEN(D2)+LEN(E2)+LEN(F2)+LEN(G2)+LEN(H2) -> 21 | R2: positive | S2: t | T2: f
A3: tai86 | B3: 1873 | C3: firmstone, w | H3: easton pa | P3: =LEN(C3)+LEN(D3)+LEN(E3)+LEN(F3)+LEN(G3)+LEN(H3) -> 21 | R3: negative | S3: f | T3: t
A4: tai137 | B4: 1873 | C4: humphreys, a | H4: new york city | P4: =LEN(C4)+LEN(D4)+LEN(E4)+LEN(F4)+LEN(G4)+LEN(H4) -> 25
A5: tai152 | B5: 1873 | C5: k, n | G5: fountain mill | H5: westmoreland co pa | I5: b | M5: b | N5: b | P5: =LEN(C5)+LEN(D5)+LEN(E5)+LEN(F5)+LEN(G5)+LEN(H5) -> 35 | R5: code
A6: tai201 | B6: 1873 | C6: pearse, j | H6: dauphin co pa | M6: b | N6: b | P6: =LEN(C6)+LEN(D6)+LEN(E6)+LEN(F6)+LEN(G6)+LEN(H6) -> 22 | R6: extracted/actual | S6: positive | T6: negative
A7: tai251 | B7: 1873 | C7: symincton, w | H7: brooklyn n y | I7: b | P7: =LEN(C7)+LEN(D7)+LEN(E7)+LEN(F7)+LEN(G7)+LEN(H7) -> 24 | R7: positive | T7: f
A8: tai287 | B8: 1876 | C8: allen, o | H8: new haven conn | P8: =LEN(C8)+LEN(D8)+LEN(E8)+LEN(F8)+LEN(G8)+LEN(H8) -> 22 | R8: negative | S8: f
A9: tai301 | B9: 1876 | C9: beardslek, c | G9: u.s. navy | H9: washington d.c. | P9: =LEN(C9)+LEN(D9)+LEN(E9)+LEN(F9)+LEN(G9)+LEN(H9) -> 36
A10: tai307 | B10: 1876 | C10: bennett, d | H10: montgomery co pa | M10: b | N10: b | P10: =LEN(C10)+LEN(D10)+LEN(E10)+LEN(F10)+LEN(G10)+LEN(H10) -> 26 | R10: types of mistakes on true positives
A11: tai336 | B11: 1876 | C11: bowir, a | H11: san francisco cal | I11: a | O11: 2 | P11: =LEN(C11)+LEN(D11)+LEN(E11)+LEN(F11)+LEN(G11)+LEN(H11) -> 25 | R11: no mistake
A12: tai367 | B12: 1876 | C12: burden, i | H12: troy n y | P12: =LEN(C12)+LEN(D12)+LEN(E12)+LEN(F12)+LEN(G12)+LEN(H12) -> 17 | R12: source to text | S12: a
A13: tai374 | B13: 1876 | C13: burtue, p | H13: paris france | I13: a | J13: b | O13: 3 | P13: =LEN(C13)+LEN(D13)+LEN(E13)+LEN(F13)+LEN(G13)+LEN(H13) -> 21 | R13: text to class | S13: b
A14: tai430 | B14: 1876 | C14: croxton, s | H14: canal dover ohio | N14: b | P14: =LEN(C14)+LEN(D14)+LEN(E14)+LEN(F14)+LEN(G14)+LEN(H14) -> 26
A15: tai457 | B15: 1876 | C15: duval, c | G15: care wm. ford | H15: san francisco cal | M15: b | N15: b | P15: =LEN(C15)+LEN(D15)+LEN(E15)+LEN(F15)+LEN(G15)+LEN(H15) -> 38
A16: tai462 | B16: 1876 | C16: ellsworta, a | G16: care union iron works | H16: san francisco cal | I16: a | O16: 1 | P16: =LEN(C16)+LEN(D16)+LEN(E16)+LEN(F16)+LEN(G16)+LEN(H16) -> 50
A17: tai547 | B17: 1876 | C17: harden, o | H17: charleston s. c. | N17: b | P17: =LEN(C17)+LEN(D17)+LEN(E17)+LEN(F17)+LEN(G17)+LEN(H17) -> 25
A18: tai593 | B18: 1876 | C18: humphreys, a | H18: new york city | P18: =LEN(C18)+LEN(D18)+LEN(E18)+LEN(F18)+LEN(G18)+LEN(H18) -> 25
A19: tai665 | B19: 1876 | C19: macfarlane, t | H19: quebec canada. | J19: b | P19: =LEN(C19)+LEN(D19)+LEN(E19)+LEN(F19)+LEN(G19)+LEN(H19) -> 27
A20: tai699 | B20: 1876 | C20: mickley, e | H20: hokendauqua pa | P20: =LEN(C20)+LEN(D20)+LEN(E20)+LEN(F20)+LEN(G20)+LEN(H20) -> 24
A21: tai813 | B21: 1876 | C21: ropinson, l | H21: philadelphia pa | I21: a | O21: 2 | P21: =LEN(C21)+LEN(D21)+LEN(E21)+LEN(F21)+LEN(G21)+LEN(H21) -> 26
A22: tai973 | B22: 1876 | C22: wood, h | H22: streator ill | M22: b | P22: =LEN(C22)+LEN(D22)+LEN(E22)+LEN(F22)+LEN(G22)+LEN(H22) -> 19
A23: tai984 | B23: 1877 | C23: agasiz, a | H23: cambridge mass | I23: a | L23: b | O23: 2 | P23: =LEN(C23)+LEN(D23)+LEN(E23)+LEN(F23)+LEN(G23)+LEN(H23) -> 23
A24: tai1030 | B24: 1877 | C24: bonnell, s | H24: new york city | P24: =LEN(C24)+LEN(D24)+LEN(E24)+LEN(F24)+LEN(G24)+LEN(H24) -> 23
A25: tai1093 | B25: 1877 | C25: champin, h | H25: chateauneuf de mazenc dr me | N25: a | O25: 3 | P25: =LEN(C25)+LEN(D25)+LEN(E25)+LEN(F25)+LEN(G25)+LEN(H25) -> 37
A26: tai1220 | B26: 1877 | C26: garlick, e | H26: indianapolis ind | P26: =LEN(C26)+LEN(D26)+LEN(E26)+LEN(F26)+LEN(G26)+LEN(H26) -> 26
A27: tai1287 | B27: 1877 | C27: haut, r | G27: eliza furnaces | H27: pittsburgh pa | P27: =LEN(C27)+LEN(D27)+LEN(E27)+LEN(F27)+LEN(G27)+LEN(H27) -> 34
A28: tai1307 | B28: 1877 | C28: himrop, c | H28: youngstown ohio | I28: a | O28: 2 | P28: =LEN(C28)+LEN(D28)+LEN(E28)+LEN(F28)+LEN(G28)+LEN(H28) -> 24
A29: tai1354 | B29: 1877 | C29: kelly, r | H29: new york city | P29: =LEN(C29)+LEN(D29)+LEN(E29)+LEN(F29)+LEN(G29)+LEN(H29) -> 21
A30: tai1376 | B30: 1877 | C30: lauder, w | F30: manager | H30: riddlesburg pa | L30: b | M30: b | P30: =LEN(C30)+LEN(D30)+LEN(E30)+LEN(F30)+LEN(G30)+LEN(H30) -> 30
A31: tai1469 | B31: 1877 | C31: olcott, e | G31: orinoco exploring and mining co. | H31: walnut st philada | P31: =LEN(C31)+LEN(D31)+LEN(E31)+LEN(F31)+LEN(G31)+LEN(H31) -> 58
A32: tai1494 | B32: 1877 | C32: pickanps, h | H32: nelsonville ohio | I32: a | O32: 4 | P32: =LEN(C32)+LEN(D32)+LEN(E32)+LEN(F32)+LEN(G32)+LEN(H32) -> 27
A33: tai1529 | B33: 1877 | C33: raper, c | H33: easton pa | I33: a | O33: 2 | P33: =LEN(C33)+LEN(D33)+LEN(E33)+LEN(F33)+LEN(G33)+LEN(H33) -> 17
A34: tai1559 | B34: 1877 | C34: ross, w | H34: cincinnati ohio | P34: =LEN(C34)+LEN(D34)+LEN(E34)+LEN(F34)+LEN(G34)+LEN(H34) -> 22
A35: tai1570 | B35: 1877 | C35: sanders, r | H35: philadelphia pa | P35: =LEN(C35)+LEN(D35)+LEN(E35)+LEN(F35)+LEN(G35)+LEN(H35) -> 25
A36: tai1578 | B36: 1877 | C36: scott, n | H36: twenty mile stand ohio | P36: =LEN(C36)+LEN(D36)+LEN(E36)+LEN(F36)+LEN(G36)+LEN(H36) -> 30
A37: tai1596 | B37: 1877 | C37: smeaton, w | G37: columbia school of mines | H37: new york city | M37: b | P37: =LEN(C37)+LEN(D37)+LEN(E37)+LEN(F37)+LEN(G37)+LEN(H37) -> 47
A38: tai1671 | B38: 1877 | C38: warren, h | G38: care a. w. thompson | H38: san francisco cal | P38: =LEN(C38)+LEN(D38)+LEN(E38)+LEN(F38)+LEN(G38)+LEN(H38) -> 45
A39: tai1696 | B39: 1877 | C39: wickrs, g | H39: alleghany co va | I39: a | M39: b | N39: b | O39: 2 | P39: =LEN(C39)+LEN(D39)+LEN(E39)+LEN(F39)+LEN(G39)+LEN(H39) -> 24
A40: tai1810 | B40: 1880 | C40: brown, a | H40: cleveland ohio | P40: =LEN(C40)+LEN(D40)+LEN(E40)+LEN(F40)+LEN(G40)+LEN(H40) -> 22
...

Sheet mybprueba
A1: id | B1: year | C1: text | D1: company | E1: Correct
A2: myb24 | B2: 1887 | C2: For 1886-7, 10s. per share interim dividends have been paid. | D2: Adamant Diamond Mining Company Limited | E2: t
A3: myb675 | B3: 1887 | C3: the two boards which appear more advantageous to both companies than those | D3: Anglo African Diamond Mining Company | E3: t
A4: myb1359 | B4: 1887 | C4: mining, Ac. The company also possesses certain contracts and shares in the | D4: Aruba Island Gold Mining Company | E4: t
A5: myb3650 | B5: 1887 | C5: preference shares of the new company. | D5: Canadian Copper And Sulphur Company | E5: t
A6: myb4534 | B6: 1887 | C6: Less cost of mining and milling, at £2 3s. per ton... ... 10,750 | D6: Charters Towers Queensland Gold Mining | E6: t
A7: myb8055 | B7: 1887 | C7: An important feature connected with the property is that sufficient work has been done to | D7: Essaman Gold Mining Company Limited | E7: t
A8: myb8488 | B8: 1887 | C8: Liquidator s Offices. | D8: Frederick Valley Gold Mining Limited | E8: t
A9: myb10901 | B9: 1887 | C9: expectations from the lowest to the furthest extended part of the mine. | D9: Indian Consolidated Gold Company Limited | E9: t
A10: myb12462 | B10: 1887 | C10: but half-yearly meetings are held in May to receive the agent s report. The | D10: Leadhills Silver Lead Mining And | E10: t
A11: myb15562 | B11: 1887 | C11: Secretary. Offices. | D11: New Emma Silver Mining Company | E11: t
A12: myb22289 | B12: 1887 | C12: tbe damage sustained at the mine. | D12: South Darren Mining Company Limited | E12: t
A13: myb23311 | B13: 1887 | C13: TASMANIAN TIN MINING COMPANY, | D13: Tasmanian Tin Mining Company Limited | E13: t
... A40: myb93570 | B40: 1891 | C40: Sinclair MacLeay, merchant, 167, Winchester | D40: Adventurers Ashanti And Wassau Limited | E40: b
A41: myb94175 | B41: 1891 | C41: Solicitors. Mining Manager. Auditor. | D41: Anglo Saxon Gold Mining Syndicate
A42: myb99090 | B42: 1891 | C42: allotted is 16,000, on which £8,687 10s. has been paid, being 10s. 3d. per share | D42: Day Dawn And Norfolk Mines
A43: myb107745 | B43: 1891 | C43: Auditor. Secretary. Offices. | D43: New Pittsburg Grass Valley Gold
A44: myb108524 | B44: 1891 | C44: have been retained. | D44: North Australian Mining Company Limited
A45: myb110915 | B45: 1891 | C45: ment, and the balance as required in sums of 2s., at intervals of not less than | D45: Quindio Quicksilver Mines Limited
A46: myb117300 | B46: 1891 | C46: Howard Hodges. 17 and 18, Basinghall Street, E.C. | D46: Barrett Gold Mining Company Limited
A47: myb119625 | B47: 1891 | C47: developing Matabeleland and territories in South ana Central Africa, and arrangements were | D47: Exploring Land Minerals Limited
A48: myb120632 | B48: 1891 | C48: GRIQUALAND WEST DIAMOND MINING COMPANY, | D48: Griqualand West Diamond Mining Company
A49: myb120861 | B49: 1891 | C49: tain if any of the reefs make below it, before going to the expense of sinking permanent shafts | D49: Henderson And Forbes Gold Mining
A50: myb127065 | B50: 1891 | C50: the remaining 10,000 shares at present, they decided to shut down the mine temporarily. | D50: Weltevreden Estate And Gold Mining
A51: myb136127 | B51: 1893 | C51: account of these preference Bhares the liabilities at the mine, which unfortunately accumulated | D51: Guadalupe Syndicate Limited
A52: myb142096 | B52: 1893 | C52: carried to reserve, and £818 3a. 3d. carried forward. Tho transfer form used is | D52: Nundydroog Gold Mining Company
... A284: myb835405 | B284: 1917 | C284: £33,000. | D284: Associated Queensland Mines Limited
A285: myb841789 | B285: 1917 | C285: 100000 | D285: Calumet And Hecla Mining Company
A286: myb842127 | B286: 1917 | C286: to which they were entitled on redemption. The object | D286: Camp Bird Limited Bakqiimmp
A287: myb842218 | B287: 1917 | C287: yOUI instal | D287: Canadian Collieries Dunsmuir Limited
A288: myb842391 | B288: 1917 | C288: received on shares held in the Mining Corpn. of Canada, Ltd., amounted to | D288: Canadian Mining Corporation Limited
A289: myb842705 | B289: 1917 | C289: mini was dissolved. | D289: Carabaya Mining Syndicate Limited
A290: myb846603 | B290: 1917 | C290: September 30, 1912, when the new plant, which consists | D290: Consolidated Langlaagte Mines Limited
A291: myb861246 | B291: 1917 | C291: shares Nos. | D291: Johannesburg Forest And Land Limited
A292: myb861308 | B292: 1917 | C292: the Atlas Works | D292: John Brown And Company Limited
A293: myb862015 | B293: 1917 | C293: loads; washing was suspended July, 1907, but during 1910 the blue ground on | D293: Kamfersdam Toinrs Limited
A294: myb862469 | B294: 1917 | C294: An ammonia leaching plant | D294: Kennecott Copper Corporation
A295: myb873298 | B295: 1917 | C295: NEw HERIoT GoLD MINING comPANY, LIMITED, | D295: New Heriwt Gold Mining Oopany
A296: myb874013 | B296: 1917 | C296: Havercroft and South Hiendley, four miles from | D296: New Monckton Collieries Limited
A297: myb874330 | B297: 1917 | C297: the Witwatersrand. | D297: New Radnwr Limited
...

Sheet mybprueba (2)
A1: id | B1: year | C1: text | D1: company | E1: correct
A2: 24762 | B2: 1887 | C2: quarters ending November 1, 1886, February 1 and May 2, 1887, and at the rate | D2: Viola Company Limited | E2: t
A3: 31014 | B3: 1888 | C3: has left a net profit of £1,526 5s. lod. | D3: Copiapo Mining Company Limited | E3: t
A4: 32696 | B4: 1888 | C4: DOURO GOLD MINES, LIMITED. | D4: Douro Gold Mines Limited | E4: t
A5: 76102 | B5: 1889 | C5: 1882, 9,740 | D5: Rio Tinto Company Limited | E5: t
A6: 90025 | B6: 1889 | C6: the amount placed to reserve fund and working expenses, £U,4&8 19s. 5d. ; leaving m &ea | D6: Salisbury Extension Gold Mining Company | E6: t
A7: 95364 | B7: 1891 | C7: The company is now being wound up by the Court of Chancery, an order for | D7: Bishop Creek Gold Mining Company | E7: t
A8: 108894 | B8: 1891 | C8: apatite, copper, gold, silver, lead, and other mines in Norway and Sweden. | D8: Norway Mining Corporation Limited | E8: t
A9: 126940 | B9: 1891 | C9: ANNUM, REPOKT. | D9: Wassau Gold Coast Mining Company | E9: t
A10: 139237 | B10: 1893 | C10: The director have to report that the development of tho company s property has l cen | D10: Mobuta Gold And Silveb | E10: t
A11: 146164 | B11: 1893 | C11: The authorised capital is £12,000, in 12,000 shares of £1 each, of which 7,663 | D11: Spanish Prospecting Syndicate Limited | E11: t
A12: 166547 | B12: 1894 | C12: The authorised capital is £30,000, in 30,000 shares of £1 each, of which 20,995 | D12: East Grassington Mines Limited | E12: t
A13: 166617 | B13: 1894 | C13: EAST POOL MINING COMPANY. | D13: East Pool Mining Company | E13: t
... A22: 309336 | B22: 1908 | C22: British Borneo Exploration, South West Africa Co., 4c, also debentures in the | D22: Anglo Continentall Gold Syndicate | E22: t
A23: 326850 | B23: 1908 | C23: 385842 | D23: Rio Tinto Company Limited | E23: t
A24: 328040 | B24: 1908 | C24: Thomas Honey, Chairman I Fredk. C. Marten. | H. Ghidsal. I C. C. Banc, i T. E. Honey, | D24: Servian Syndicate Limited | E24: f
A25: 334354 | B25: 1909 | C25: 3s. 6d. ; 1907 : highest, 4s. 6d. ; lowest, 3d. ; 1908 : highest, 2s. 9d. ; lowest, nil. | D25: Day Dawn Gold Mines Limited | E25: t
A26: 340092 | B26: 1909 | C26: underwriting 210,000 shares, also to the former owners of the property a sum of | D26: Tasmanian Gold Company Limited | E26: t
A27: 343048 | B27: 1909 | C27: into 143,066 ordinary and 176,250 deferred shares of 103. each, the deferred | D27: Ashan And Concessio Ite | E27: t
A28: 345460 | B28: 1909 | C28: vendors received £30,000 in fully-paid shares. In 1891 the company purchased | D28: City And Suburban Gold Mining | E28: t
A29: 352523 | B29: 1909 | C29: The authorised capital | D29: Koffyfontein Estates Limited | E29: t
A30: 362909 | B30: 1909 | C30: call on 3,427 shares was 6s., payable Juno Oth, 1907. | D30: Vaal River Diamond Company Limited | E30: t
A31: 387867 | B31: 1909 | C31: an accumulating sinking fund of £2,000 per annum, but after November 11th, | D31: Wemyss Collieries Trust Limited | E31: t
A32: 403854 | B32: 1910 | C32: share for every two shares held : | D32: Gelden Huis Deep Limited | E32: t
A33: 404537 | B33: 1910 | C33: 17,000 fully-paid shares and £3,670 debentures in the Bartie Corporation, Ltd. | D33: Gold Coast Investment Company | E33: t
A34: 436275 | B34: 1910 | C34: properties and rights at Lymni, Cyprus. The consideration was £4,000 in | D34: Lymni Copper Mining Syndicate Limited | E34: t
A35: 458483 | B35: 1911 | C35: general miners in Nigeria. The authorised capital is £6,000 in 6,000 shares of £1 | D35: Alluvi Syndicate Lnlgeri Limited | E35: t
... A95: 1075979 | B95: 1922 | C95: creditors £246; share premium account £4,708. | D95: Anglo French Ural Syndicate Limited | E95: t
A96: 1110534 | B96: 1922 | C96: 2552064 | D96: Sungel Best Mines Limited | E96: b
A97: 1116633 | B97: 1923 | C97: Africa, Ltd., 1,000 North Oogies Witbank Collieries, Ltd., 1,006 Tait and 00., | D97: African Land And Investment Limited | E97: t
A98: 1116662 | B98: 1923 | C98: District, Transvaal. In conjunction with the Southern Oregon Goldfields, Ltd., | D98: African Mining Agency Limited | E98: t
A99: 1127716 | B99: 1923 | C99: net profits from the working of the mines is to be applied in paying off the prior | D99: Dunderland Iron Ore Company Limited | E99: t
A100: 1153004 | B100: 1923 | C100: Box 2269, The Corner House, Johannesburg. | D100: Transvaal Coal Corporation Limited | E100: t
A101: 1153849 | B101: 1923 | C101: holders at par. | D101: United Collieries Limited | E101: t
E102: 11
E103: 0.89

Sheet Sheet1
B1: company/organization | C1: capital | D1: year regist | E1: location | F1: lastname | G1: firstname | H1: middlename | I1: role | J1: nationality | K1: education | L1: Overall | W1: MYB | X1: AMM | Y1: MMM | Z1: ALUMNI | AA1: AIME
A2: myb | B2: 0.43765281 | C2: 0.99266504 | D2: 0.99266504 | E2: 0.93459658 | F2: 0.88753056 | G2: 0.94132029 | H2: 0.91687042 | I2: 0.96577017 | L2: =AVERAGE(B2:K2) -> 0.88363386 | V2: Company/Organization | W2: 0.43765281 | X2: 0.73838631 | Y2: 0.92665037 | Z2: 0.72616137 | AA2: 0.89731051
A3: amm | B3: 0.73838631 | C3: 0.98777506 | D3: 0.98288509 | E3: 0.96495518 | F3: 0.83129584 | G3: 0.97555012 | H3: 0.87775061 | I3: 0.98288509 | L3: =AVERAGE(B3:K3) -> 0.91768541 | V3: Capital | W3: 0.99266504 | X3: 0.98777506 | Y3: 0.96821516 | AA3: 0
A4: mmm | B4: 0.92176039 | C4: 0.96821516 | D4: 0.99755501 | E4: 0.88997555 | F4: 0.7408313 | G4: 0.94621027 | H4: 0.76528117 | I4: 0.96332518 | L4: =AVERAGE(B4:K4) -> 0.89914425 | V4: Year Regist | W4: 0.99266504 | X4: 0.98288509 | Y4: 0.99755501 | Z4: 0.799511 | AA4: 0
A5: alumni | B5: 0.72616137 | D5: 0.799511 | F5: 0.94621027 | G5: 0.93887531 | H5: 0.66992665 | I5: 0.76772616 | L5: =AVERAGE(B5:K5) -> 0.80806846 | V5: Location | W5: 0.75794621 | X5: 0.94376528 | Y5: 0.88997555 | AA5: 0.92665037
A6: AIME | B6: 0.89731051 | E6: 0.92420538 | F6: 0.86552567 | G6: 0.86552567 | H6: 0.86552567 | I6: 0.95354523 | J6: 0.99511002 | K6: 1 | L6: =AVERAGE(B6:K6) -> 0.92084352 | V6: Lastname | W6: 0.88753056 | X6: 0.83129584 | Y6: 0.7408313 | Z6: 0.94621027 | AA6: 0.86552567
V7: Firstname | W7: 0.94132029 | X7: 0.97555012 | Y7: 0.94621027 | Z7: 0.93887531
V8: Middlename | W8: 0.91687042 | X8: 0.87775061 | Y8: 0.76528117 | Z8: 0.66992665
B9: simpname | C9: nationality | D9: edu | E9: prof | F9: org | G9: loc | V9: Role | W9: 0.96577017 | X9: 0.98288509 | Y9: 0.96332518 | Z9: 0.76772616 | AA9: 0.95599022
B10: 0.86552567 | C10: 0.99511002 | D10: 1 | V10: Nationality | AA10: 0.99511002
V11: Education | AA11: 1
B12: myb | C12: amm | D12: mmm | E12: Overall | F12: alumni | G12: AIME | H12: Overall | J12: =UPPER(A12) | K12: =UPPER(B12) -> MYB | L12: =UPPER(C12) -> AMM | M12: =UPPER(D12) -> MMM | N12: =UPPER(E12) -> OVERALL | O12: =UPPER(F12) -> ALUMNI | P12: =UPPER(G12) -> AIME | Q12: =UPPER(H12) -> OVERALL | R12: =UPPER(I12) | V12: Overall | W12: 0.86155257 | X12: 0.91503667 | Y12: 0.8997555 | Z12: 0.80806846 | AA12: 0.9400978
A13: N | B13: 409 | C13: 384 | D13: 368 | E13: =SUM(B13:D13) -> 1161 | F13: 384 | G13: 382 | H13: =SUM(F13:G13) -> 766 | J13: N | K13: =B13 -> 409 | L13: =C13 -> 384 | M13: =D13 -> 368 | N13: =E13 -> 1161 | O13: =F13 -> 384 | P13: =G13 -> 382 | Q13: =H13 -> 766 | V13: CER | W13: 0.013907582 | X13: 0.0052818592 | Y13: 0.0016250621 | Z13: 0.0032051282 | AA13: 0.010342814
